-278710 -278670 1661778326928 5136389736045157394 2530 0.7893075830503821
-278689 -278649 1661778403191 1867095691722844605 2584922 0.7909876480040376
-278688 -278648 1661779311606 2744053610208878206 1895221 0.7910587217496718
-278684 -278644 1661779385956 2420011366375456537 2151897 0.791409116112166
-278684 -278644 1661779425208 3447394444699911352 1338813 0.791409116112166
(node:17164) UnhandledPromiseRejectionWarning: Error: call revert exception; VM Exception while processing transaction: reverted with reason string "EnumerableSet: index out of bounds" [ See: https://links.ethers.org/v5-errors-CALL_EXCEPTION ] (method="tokenOfOwnerByIndex(address,uint256)", data="0x08c379a000000000000000000000000000000000000000000000000000000000000000200000000000000000000000000000000000000000000000000000000000000022456e756d657261626c655365743a20696e646578206f7574206f6620626f756e6473000000000000000000000000000000000000000000000000000000000000", errorArgs=["EnumerableSet: index out of bounds"], errorName="Error", errorSignature="Error(string)", reason="EnumerableSet: index out of bounds", code=CALL_EXCEPTION, version=abi/5.6.4)
    at Logger.makeError (C:\Users\zahar\Desktop\product pilot\alpa-router\node_modules\@ethersproject\logger\lib\index.js:233:21)
    at Logger.throwError (C:\Users\zahar\Desktop\product pilot\alpa-router\node_modules\@ethersproject\logger\lib\index.js:242:20)
    at Interface.decodeFunctionResult (C:\Users\zahar\Desktop\product pilot\alpa-router\node_modules\@ethersproject\abi\lib\interface.js:388:23)
    at Contract.<anonymous> (C:\Users\zahar\Desktop\product pilot\alpa-router\node_modules\@ethersproject\contracts\lib\index.js:395:56)
    at step (C:\Users\zahar\Desktop\product pilot\alpa-router\node_modules\@ethersproject\contracts\lib\index.js:48:23)
    at Object.next (C:\Users\zahar\Desktop\product pilot\alpa-router\node_modules\@ethersproject\contracts\lib\index.js:29:53)
    at fulfilled (C:\Users\zahar\Desktop\product pilot\alpa-router\node_modules\@ethersproject\contracts\lib\index.js:20:58)
    at processTicksAndRejections (internal/process/task_queues.js:97:5)
(node:17164) UnhandledPromiseRejectionWarning: Unhandled promise rejection. This error originated either by throwing inside of an async function without a catch block, or by rejecting a promise which was not handled with .catch(). To terminate the node process on unhandled promise rejection, use the CLI flag `--unhandled-rejections=strict` (see https://nodejs.org/api/cli.html#cli_unhandled_rejections_mode). (rejection id: 6)
(node:17164) [DEP0018] DeprecationWarning: Unhandled promise rejections are deprecated. In the future, promise rejections that are not handled will terminate the Node.js process with a non-zero exit code.
-278636 -278556 1661780855237 3447394444699911352 1338813 0.7967777000090285
-278580 -278500 1661782085007 1598504520261219548 2825086 0.8012172807184698
-278573 -278493 1661782494381 989030019736346 4112051 0.8017991641880309
-278521 -278441 1661782533073 2479385720541355773 2113765 0.8060227894461819
-278506 -278426 1661782570386 1421694312665181106 2969242 0.8072013704807461
-278463 -278383 1661782608837 2680180073844988305 1953691 0.8107177201339183
-278442 -278362 1661782659147 1494999917388374640 2918580 0.8124056004987995
-278422 -278342 1661782697048 3434714675822589429 1340794 0.8140226017411549
-278420 -278340 1661782735427 3609033335732875869 1199962 0.8141499765095629
-278421 -278341 1661782779837 3325225391400145525 1431020 0.8141206208529187
-278365 -278285 1661783066494 3084313488103031876 1628164 0.8186446278144667
-278365 -278285 1661783104933 3136087337089732510 1585780 0.8186297092705365
-278366 -278286 1661783143856 3138757250861710095 1583594 0.818604487116881
-278398 -278318 1661783182946 3776724079133755711 1062913 0.8159546357285946
-278406 -278326 1661783222186 3303746532888702055 1448897 0.8153061685644455
-278398 -278318 1661783259824 3163265996455838413 1563537 0.8159391940016262
-278395 -278315 1661783296602 3288534963615707565 1461239 0.8162039338328818
-278396 -278316 1661783336078 3117617561748287960 1600754 0.8161250528433608
-278395 -278315 1661783374080 3117599049866073087 1600768 0.816186154766482
(node:8348) UnhandledPromiseRejectionWarning: Error: call revert exception; VM Exception while processing transaction: reverted with reason string "EnumerableSet: index out of bounds" [ See: https://links.ethers.org/v5-errors-CALL_EXCEPTION ] (method="tokenOfOwnerByIndex(address,uint256)", data="0x08c379a000000000000000000000000000000000000000000000000000000000000000200000000000000000000000000000000000000000000000000000000000000022456e756d657261626c655365743a20696e646578206f7574206f6620626f756e6473000000000000000000000000000000000000000000000000000000000000", errorArgs=["EnumerableSet: index out of bounds"], errorName="Error", errorSignature="Error(string)", reason="EnumerableSet: index out of bounds", code=CALL_EXCEPTION, version=abi/5.6.4)
    at Logger.makeError (C:\Users\zahar\Desktop\product pilot\alpa-router\node_modules\@ethersproject\logger\lib\index.js:233:21)
    at Logger.throwError (C:\Users\zahar\Desktop\product pilot\alpa-router\node_modules\@ethersproject\logger\lib\index.js:242:20)
    at Interface.decodeFunctionResult (C:\Users\zahar\Desktop\product pilot\alpa-router\node_modules\@ethersproject\abi\lib\interface.js:388:23)
    at Contract.<anonymous> (C:\Users\zahar\Desktop\product pilot\alpa-router\node_modules\@ethersproject\contracts\lib\index.js:395:56)
    at step (C:\Users\zahar\Desktop\product pilot\alpa-router\node_modules\@ethersproject\contracts\lib\index.js:48:23)
    at Object.next (C:\Users\zahar\Desktop\product pilot\alpa-router\node_modules\@ethersproject\contracts\lib\index.js:29:53)
    at fulfilled (C:\Users\zahar\Desktop\product pilot\alpa-router\node_modules\@ethersproject\contracts\lib\index.js:20:58)
    at processTicksAndRejections (internal/process/task_queues.js:97:5)
(node:8348) UnhandledPromiseRejectionWarning: Unhandled promise rejection. This error originated either by throwing inside of an async function without a catch block, or by rejecting a promise which was not handled with .catch(). To terminate the node process on unhandled promise rejection, use the CLI flag `--unhandled-rejections=strict` (see https://nodejs.org/api/cli.html#cli_unhandled_rejections_mode). (rejection id: 20)
(node:8348) [DEP0018] DeprecationWarning: Unhandled promise rejections are deprecated. In the future, promise rejections that are not handled will terminate the Node.js process with a non-zero exit code.
